2023-07-17 11:29:14,934 INFO    StreamThr :38780 [internal.py:wandb_internal():88] W&B internal server running at pid: 38780, started at: 2023-07-17 11:29:14.933218
2023-07-17 11:29:14,946 DEBUG   HandlerThread:38780 [handler.py:handle_request():138] handle_request: status
2023-07-17 11:29:14,949 DEBUG   SenderThread:38780 [sender.py:send_request():317] send_request: status
2023-07-17 11:29:14,953 INFO    WriterThread:38780 [datastore.py:open_for_write():75] open: /home/jacob/Desktop/CQA3ds/wandb/offline-run-20230717_112914-tow8yihi/run-tow8yihi.wandb
2023-07-17 11:29:14,976 DEBUG   HandlerThread:38780 [handler.py:handle_request():138] handle_request: run_start
2023-07-17 11:29:14,978 DEBUG   HandlerThread:38780 [meta.py:__init__():34] meta init
2023-07-17 11:29:14,979 DEBUG   HandlerThread:38780 [meta.py:__init__():49] meta init done
2023-07-17 11:29:14,979 DEBUG   HandlerThread:38780 [meta.py:probe():215] probe
2023-07-17 11:29:14,987 DEBUG   HandlerThread:38780 [meta.py:_setup_git():205] setup git
2023-07-17 11:29:15,008 DEBUG   HandlerThread:38780 [meta.py:_setup_git():212] setup git done
2023-07-17 11:29:15,008 DEBUG   HandlerThread:38780 [meta.py:_save_pip():53] save pip
2023-07-17 11:29:15,011 DEBUG   HandlerThread:38780 [meta.py:_save_pip():67] save pip done
2023-07-17 11:29:15,011 DEBUG   HandlerThread:38780 [meta.py:_save_conda():74] save conda
2023-07-17 11:29:15,017 ERROR   HandlerThread:38780 [meta.py:_save_conda():83] Error saving conda packages
Traceback (most recent call last):
  File "/home/jacob/miniconda3/envs/38b/lib/python3.8/site-packages/wandb/sdk/internal/meta.py", line 79, in _save_conda
    subprocess.call(
  File "/home/jacob/miniconda3/envs/38b/lib/python3.8/subprocess.py", line 340, in call
    with Popen(*popenargs, **kwargs) as p:
  File "/home/jacob/miniconda3/envs/38b/lib/python3.8/subprocess.py", line 858, in __init__
    self._execute_child(args, executable, preexec_fn, close_fds,
  File "/home/jacob/miniconda3/envs/38b/lib/python3.8/subprocess.py", line 1704, in _execute_child
    raise child_exception_type(errno_num, err_msg, err_filename)
FileNotFoundError: [Errno 2] No such file or directory: 'conda'
2023-07-17 11:29:15,019 DEBUG   HandlerThread:38780 [meta.py:_save_conda():84] save conda done
2023-07-17 11:29:15,019 DEBUG   HandlerThread:38780 [meta.py:probe():253] probe done
